<?xml version="1.0" ?>

<!-- Basic WAM-V with gazebo plugins for dynamics -->
<robot name="aquabot">
  <link name="aquabot/left_battery_link">
    <visual>
      <origin rpy="0 0 0" xyz="0 -1.03 -.45"/>
      <geometry>
        <mesh filename="package://aquabot_description/mesh/vrx/battery.dae"/>
      </geometry>
    </visual>
    <collision name="left_battery_collision">
      <origin rpy="0 0 0" xyz="0 0 .15"/>
      <geometry>
        <box size=".6 .4 .31"/>
      </geometry>
    </collision>
    <inertial>
      <origin rpy=" 0 0 0" xyz="0 0 .15"/>
      <mass value="23.5"/>
      <inertia ixx="0.5015291666666667" ixy="0" ixz="0" iyy="0.8931958333333333" iyz="0" izz="1.0183333333333333"/>
    </inertial>
  </link>
  <joint name="aquabot/left_chasis_battery_joint" type="fixed">
    <origin rpy="0 0 0" xyz="0 0.63 0.87"/>
    <parent link="aquabot/base_link"/>
    <child link="aquabot/left_battery_link"/>
  </joint>
  <link name="aquabot/right_battery_link">
    <visual>
      <origin rpy="0 0 0" xyz="0 -1.03 -.45"/>
      <geometry>
        <mesh filename="package://aquabot_description/mesh/vrx/battery.dae"/>
      </geometry>
    </visual>
    <collision name="right_battery_collision">
      <origin rpy="0 0 0" xyz="0 0 .15"/>
      <geometry>
        <box size=".6 .4 .31"/>
      </geometry>
    </collision>
    <inertial>
      <origin rpy=" 0 0 0" xyz="0 0 .15"/>
      <mass value="23.5"/>
      <inertia ixx="0.5015291666666667" ixy="0" ixz="0" iyy="0.8931958333333333" iyz="0" izz="1.0183333333333333"/>
    </inertial>
  </link>
  <joint name="aquabot/right_chasis_battery_joint" type="fixed">
    <origin rpy="0 0 0" xyz="0 -0.63 0.87"/>
    <parent link="aquabot/base_link"/>
    <child link="aquabot/right_battery_link"/>
  </joint>
  <!-- Basic model of the 16' WAM-V USV -->
  <link name="aquabot/base_link">
    <visual>
      <geometry>
        <mesh filename="package://aquabot_description/mesh/blue_boat.dae"/>
      </geometry>
    </visual>
    <!-- Simple model collision (tested) -->
    <collision name="main_float">
      <geometry>
        <mesh filename="package://aquabot_description/mesh/blue_boat.dae"/>
      </geometry>
    </collision>
    <collision name="rear">
      <origin rpy=" 0 0 0" xyz="-3.5 0 0"/>
      <geometry>
        <box size="0.05 1.5 1.0"/>
      </geometry>
    </collision>
    <inertial>
      <!-- From WAM-V spec sheet -->
      <mass value="1000.0"/>
      <inertia ixx="120.0" ixy="0.0" ixz="0.0" iyy="393" iyz="0.0" izz="446.0"/>
    </inertial>
  </link>
  <gazebo>
    <enable_wind>true</enable_wind>
  </gazebo>
  <gazebo reference="aquabot/base_link">
    <sensor name="contact_sensor" type="contact">
      <contact>
        <!-- collisions are renamed during urdf -> sdf fixed joint lumping -->
        <collision>aquabot/base_link_fixed_joint_lump__main_float_collision</collision>
        <collision>aquabot/base_link_fixed_joint_lump__rear_collision_1</collision>
        <topic>/vrx/contacts</topic>
      </contact>
      <always_on>1</always_on>
      <update_rate>5</update_rate>
    </sensor>
  </gazebo>
  <link name="aquabot/left_engine_link">
    <visual>
      <geometry>
        <mesh filename="package://aquabot_description/mesh/vrx/engine.dae"/>
      </geometry>
    </visual>
    <collision name="left_engine_vertical_axis_collision">
      <origin rpy="0 0 0" xyz="-0.16 0 -0.24"/>
      <geometry>
        <box size="0.2 0.15 0.83"/>
      </geometry>
    </collision>
    <collision name="left_engine_rear_end_collision">
      <origin rpy="0 0 0" xyz="-0.34 0 0.12"/>
      <geometry>
        <box size="0.12 0.15 0.12"/>
      </geometry>
    </collision>
    <inertial>
      <mass value="15"/>
      <inertia ixx="0.889245" ixy="0.0" ixz="0.0" iyy="0.911125" iyz="0.0" izz="0.078125"/>
    </inertial>
  </link>
  <link name="aquabot/left_propeller_link">
    <visual>
      <geometry>
        <mesh filename="package://aquabot_description/mesh/vrx/propeller.dae"/>
      </geometry>
    </visual>
    <collision name="left_propeller_collision">
      <origin rpy="0 1.57 0" xyz="-0.08 0 0"/>
      <geometry>
        <cylinder length="0.18" radius="0.24"/>
      </geometry>
    </collision>
    <inertial>
      <mass value="0.5"/>
      <inertia ixx="0.008545" ixy="0.0" ixz="0.0" iyy="0.008545" iyz="0.0" izz="0.0144"/>
    </inertial>
  </link>
  <joint name="aquabot/left_chassis_engine_joint" type="revolute">
    <axis xyz="0 0 1"/>
    <limit effort="10" lower="-0.78539816339" upper="0.78539816339" velocity="10"/>
    <origin rpy="0.0 0.0 0.0" xyz="-3 0.6 0.318237"/>
    <parent link="aquabot/base_link"/>
    <child link="aquabot/left_engine_link"/>
    <dynamics damping="10" friction="5"/>
  </joint>
  <joint name="aquabot/left_engine_propeller_joint" type="continuous">
    <axis rpy="0 0 0" xyz="1 0 0"/>
    <parent link="aquabot/left_engine_link"/>
    <child link="aquabot/left_propeller_link"/>
    <origin rpy="0 0 0" xyz="-0.278156 0 -0.509371"/>
    <limit effort="100" velocity="100"/>
    <dynamics damping="0.05" friction="0.05"/>
  </joint>
  <link name="aquabot/right_engine_link">
    <visual>
      <geometry>
        <mesh filename="package://aquabot_description/mesh/vrx/engine.dae"/>
      </geometry>
    </visual>
    <collision name="right_engine_vertical_axis_collision">
      <origin rpy="0 0 0" xyz="-0.16 0 -0.24"/>
      <geometry>
        <box size="0.2 0.15 0.83"/>
      </geometry>
    </collision>
    <collision name="right_engine_rear_end_collision">
      <origin rpy="0 0 0" xyz="-0.34 0 0.12"/>
      <geometry>
        <box size="0.12 0.15 0.12"/>
      </geometry>
    </collision>
    <inertial>
      <mass value="15"/>
      <inertia ixx="0.889245" ixy="0.0" ixz="0.0" iyy="0.911125" iyz="0.0" izz="0.078125"/>
    </inertial>
  </link>
  <link name="aquabot/right_propeller_link">
    <visual>
      <geometry>
        <mesh filename="package://aquabot_description/mesh/vrx/propeller.dae"/>
      </geometry>
    </visual>
    <collision name="right_propeller_collision">
      <origin rpy="0 1.57 0" xyz="-0.08 0 0"/>
      <geometry>
        <cylinder length="0.18" radius="0.24"/>
      </geometry>
    </collision>
    <inertial>
      <mass value="0.5"/>
      <inertia ixx="0.008545" ixy="0.0" ixz="0.0" iyy="0.008545" iyz="0.0" izz="0.0144"/>
    </inertial>
  </link>
  <joint name="aquabot/right_chassis_engine_joint" type="revolute">
    <axis xyz="0 0 1"/>
    <limit effort="10" lower="-0.78539816339" upper="0.78539816339" velocity="10"/>
    <origin rpy="0.0 0.0 0.0" xyz="-3 -0.6 0.318237"/>
    <parent link="aquabot/base_link"/>
    <child link="aquabot/right_engine_link"/>
    <dynamics damping="10" friction="5"/>
  </joint>
  <joint name="aquabot/right_engine_propeller_joint" type="continuous">
    <axis rpy="0 0 0" xyz="1 0 0"/>
    <parent link="aquabot/right_engine_link"/>
    <child link="aquabot/right_propeller_link"/>
    <origin rpy="0 0 0" xyz="-0.278156 0 -0.509371"/>
    <limit effort="100" velocity="100"/>
    <dynamics damping="0.05" friction="0.05"/>
  </joint>
  <gazebo>
    <plugin filename="ignition-gazebo-thruster-system" name="ignition::gazebo::systems::Thruster">
      <joint_name>aquabot/left_engine_propeller_joint</joint_name>
      <thrust_coefficient>0.004422</thrust_coefficient>
      <fluid_density>1000</fluid_density>
      <propeller_diameter>0.2</propeller_diameter>
      <velocity_control>true</velocity_control>
      <!-- max total thrust / 2 -->
      <max_thrust_cmd>5000.0</max_thrust_cmd>
      <namespace>aquabot</namespace>
      <topic>thrusters/left/thrust</topic>
      <!-- Not used by Gazebo but used to run the bridge easily -->
      <name>left</name>
    </plugin>
    <plugin filename="ignition-gazebo-joint-position-controller-system" name="ignition::gazebo::systems::JointPositionController">
      <joint_name>aquabot/left_chassis_engine_joint</joint_name>
      <use_velocity_commands>true</use_velocity_commands>
      <topic>aquabot/thrusters/left/pos</topic>
      <!-- Not used by Gazebo but used to run the bridge easily -->
      <name>left</name>
    </plugin>
  </gazebo>
  <gazebo>
    <plugin filename="ignition-gazebo-thruster-system" name="ignition::gazebo::systems::Thruster">
      <joint_name>aquabot/right_engine_propeller_joint</joint_name>
      <thrust_coefficient>0.004422</thrust_coefficient>
      <fluid_density>1000</fluid_density>
      <propeller_diameter>0.2</propeller_diameter>
      <velocity_control>true</velocity_control>
      <!-- max total thrust / 2 -->
      <max_thrust_cmd>5000.0</max_thrust_cmd>
      <namespace>aquabot</namespace>
      <topic>thrusters/right/thrust</topic>
      <!-- Not used by Gazebo but used to run the bridge easily -->
      <name>right</name>
    </plugin>
    <plugin filename="ignition-gazebo-joint-position-controller-system" name="ignition::gazebo::systems::JointPositionController">
      <joint_name>aquabot/right_chassis_engine_joint</joint_name>
      <use_velocity_commands>true</use_velocity_commands>
      <topic>aquabot/thrusters/right/pos</topic>
      <!-- Not used by Gazebo but used to run the bridge easily -->
      <name>right</name>
    </plugin>
  </gazebo>
  <gazebo>
    <plugin filename="ignition-gazebo-joint-position-controller-system" name="ignition::gazebo::systems::JointPositionController">
      <joint_name>aquabot/base_to_main_camera_post_joint</joint_name>
      <use_velocity_commands>true</use_velocity_commands>
      <topic>aquabot/thrusters/main_camera_sensor/pos</topic>
      <!-- Not used by Gazebo but used to run the bridge easily -->
      <name>main_camera_sensor</name>
    </plugin>
  </gazebo>
  <!--Gazebo Plugin for simulating WAM-V dynamics-->
  <gazebo>
    <!-- Left hull -->
    <plugin filename="libSurface.so" name="vrx::Surface">
      <link_name>aquabot/base_link</link_name>
      <hull_length>6.0</hull_length>
      <hull_radius>0.36</hull_radius>
      <fluid_level>0</fluid_level>
      <points>
        <point>1.4 1.03 0</point>
        <point>-1.4 1.03 0</point>
      </points>
      <wavefield>
        <topic>/vrx/wavefield/parameters</topic>
      </wavefield>
    </plugin>
    <!-- Right hull -->
    <plugin filename="libSurface.so" name="vrx::Surface">
      <link_name>aquabot/base_link</link_name>
      <hull_length>6.0</hull_length>
      <hull_radius>0.36</hull_radius>
      <fluid_level>0</fluid_level>
      <points>
        <point>1.4 -1.03 0</point>
        <point>-1.4 -1.03 0</point>
      </points>
      <wavefield>
        <topic>/vrx/wavefield/parameters</topic>
      </wavefield>
    </plugin>
    <plugin filename="libSimpleHydrodynamics.so" name="vrx::SimpleHydrodynamics">
      <link_name>aquabot/base_link</link_name>
      <!-- Added mass -->
      <xDotU>0.0</xDotU>
      <yDotV>0.0</yDotV>
      <nDotR>0.0</nDotR>
      <!-- Added mass in yaw direction [kgm^2] -->
      <!-- Linear and quadratic drag -->
      <xU>182.0</xU>
      <xUU>224.0</xUU>
      <yV>183.0</yV>
      <!-- Stability derivative, 1st order, y component [kg] -->
      <yVV>149.0</yVV>
      <!-- Stability derivative, 2nd order, y component [kg/m] -->
      <zW>1000.0</zW>
      <kP>550.0</kP>
      <kPP>734.0</kPP>
      <mQ>1349.0</mQ>
      <mQQ>1102.0</mQQ>
      <nR>1199.0</nR>
      <!-- Stability derivative, 1st order, yaw component [kg/m] -->
      <nRR>979.0</nRR>
      <!-- Stability derivative, 2nd order, yaw component [kg/m^2] -->
    </plugin>
  </gazebo>
  <!-- === [Un]lock the robot to the world === -->
  <gazebo>
    <plugin filename="ignition-gazebo-detachable-joint-system" name="ignition::gazebo::systems::DetachableJoint">
      <parent_link>aquabot/base_link</parent_link>
      <child_model>platform</child_model>
      <child_link>dummy_upper</child_link>
      <topic>/vrx/release</topic>
      <suppress_child_warning>true</suppress_child_warning>
    </plugin>
  </gazebo>
  <!-- === TF === -->
  <!-- Publish robot state information -->
  <gazebo>
    <plugin filename="libignition-gazebo-pose-publisher-system.so" name="ignition::gazebo::systems::PosePublisher">
      <publish_link_pose>false</publish_link_pose>
      <publish_sensor_pose>true</publish_sensor_pose>
      <publish_collision_pose>true</publish_collision_pose>
      <publish_visual_pose>false</publish_visual_pose>
      <publish_nested_model_pose>false</publish_nested_model_pose>
      <publish_model_pose>false</publish_model_pose>
      <use_pose_vector_msg>true</use_pose_vector_msg>
      <static_publisher>false</static_publisher>
      <static_update_frequency>1</static_update_frequency>
    </plugin>
    <plugin filename="ignition-gazebo-joint-state-publisher-system" name="ignition::gazebo::systems::JointStatePublisher">
    </plugin>
  </gazebo>
  <!-- Monocular Camera -->
  <link name="aquabot/main_camera_link">
    <visual>
      <origin rpy="0 0 1.5707963267948966" xyz="-0.033 0 0"/>
      <geometry>
        <mesh filename="package://aquabot_description/mesh/vrx/mono_camera.dae"/>
      </geometry>
    </visual>
    <collision name="main_camera_lens_collision">
      <origin rpy="0 1.5707963267948966 0" xyz="0.018 0 0"/>
      <geometry>
        <cylinder length="0.042" radius="0.015"/>
      </geometry>
    </collision>
    <collision name="main_camera_box_collision">
      <origin rpy="0 0 0" xyz="-0.0205 0 0"/>
      <geometry>
        <box size="0.036 0.03 0.03"/>
      </geometry>
    </collision>
    <!-- Model inertia as box with <size>0.078 0.03 0.03</size> -->
    <inertial>
      <mass value="0.3"/>
      <inertia ixx="0.0000450" ixy="0" ixz="0" iyy="0.0001746" iyz="0" izz="0.0001746"/>
    </inertial>
  </link>
  <!-- Define a link for the optical frame.  This will match the sensor frame and
         be oriented in the camera convention. -->
  <link name="aquabot/main_camera_link_optical">
    </link>
  <!-- Sensor post -->
  <link name="aquabot/main_camera_post_link">
    <visual>
      <geometry>
        <cylinder length="0.6765" radius="0.0076"/>
      </geometry>
      <material name="main_camera_post_material">
        <color rgba="0.0 0.0 0.0 1.0"/>
      </material>
    </visual>
    <collision name="main_camera_post_collision">
      <geometry>
        <cylinder length="0.6765" radius="0.0076"/>
      </geometry>
    </collision>
    <inertial>
      <mass value="0.60885"/>
      <inertia ixx="0.023228922828375" ixy="0" ixz="0" iyy="0.023228922828375" iyz="0" izz="1.7583588e-05"/>
    </inertial>
  </link>
  <!-- Sensor post arm -->
  <link name="aquabot/main_camera_post_arm_link">
    <visual name="main_camera_post_arm_visual">
      <origin rpy="-1.0471975511965976 0 -1.5707963267948966" xyz="-0.038 0 -0.003"/>
      <geometry>
        <mesh filename="package://aquabot_description/mesh/vrx/sensor_post_arm.dae"/>
      </geometry>
    </visual>
    <collision name="main_camera_post_arm_collision">
      <origin rpy="-1.2042771838760873 0 -1.5707963267948966" xyz="0 0 0"/>
      <geometry>
        <cylinder length="0.065" radius="0.008"/>
      </geometry>
    </collision>
    <inertial>
      <origin rpy="-1.2042771838760873 0 -1.5707963267948966" xyz="0 0 0"/>
      <mass value="0.1"/>
      <inertia ixx="0.00003680833" ixy="0" ixz="0" iyy="0.00003680833" iyz="0" izz="0.00000320000"/>
    </inertial>
  </link>
  <joint name="aquabot/base_to_main_camera_post_joint" type="continuous">
    <axis xyz="0 0 1"/>
    <limit effort="5" velocity="5"/>
    <origin rpy="0 0 0.0" xyz="1.45 0.0 1.63475"/>
    <parent link="aquabot/base_link"/>
    <child link="aquabot/main_camera_post_link"/>
    <dynamics damping="1" friction="1"/>
  </joint>
  <!-- Sensor post to sensor post arm joint -->
  <joint name="aquabot/main_camera_post_to_main_camera_post_arm_joint" type="fixed">
    <origin rpy="0 0 0" xyz="0.03 0 0.33825000000000005"/>
    <parent link="aquabot/main_camera_post_link"/>
    <child link="aquabot/main_camera_post_arm_link"/>
  </joint>
  <!-- Sensor post arm to camera joint -->
  <joint name="aquabot/main_camera_post_arm_to_main_camera_joint" type="fixed">
    <origin rpy="0.0 0.08726646259971647 0.0" xyz="0.02 0 0.027"/>
    <parent link="aquabot/main_camera_post_arm_link"/>
    <child link="aquabot/main_camera_link"/>
  </joint>
  <!-- Camera to optical frame joint.  This is oriented to convert between ENU
         and camera conventions -->
  <joint name="aquabot/main_camera_to_main_camera_link_optical_joint" type="fixed">
    <origin rpy="-1.5707963267948966 0 -1.5707963267948966" xyz="0 0 0"/>
    <parent link="aquabot/main_camera_link"/>
    <child link="aquabot/main_camera_link_optical"/>
  </joint>
  <!-- Gazebo camera setup -->
  <gazebo reference="aquabot/main_camera_link">
    <sensor name="main_camera_sensor" type="camera">
      <update_rate>10.0</update_rate>
      <camera name="main_camera_camera">
        <horizontal_fov>1.3962634</horizontal_fov>
        <image>
          <width>720</width>
          <height>576</height>
          <format>R8G8B8</format>
        </image>
        <clip>
          <near>0.05</near>
          <far>400</far>
        </clip>
        <noise>
          <type>gaussian</type>
          <!-- Noise is sampled independently per pixel on each frame.
                 That pixel's noise value is added to each of its color
                 channels, which at that point lie in the range [0,1]. -->
          <mean>0.0</mean>
          <stddev>0.007</stddev>
        </noise>
      </camera>
    </sensor>
  </gazebo>
  <link name="aquabot/gps_link">
    <visual name="gps_visual">
      <geometry>
        <mesh filename="package://aquabot_description/mesh/vrx/gps.dae"/>
      </geometry>
    </visual>
    <collision name="gps_collision_base">
      <origin rpy="0 0 0" xyz="0 0 0.025"/>
      <geometry>
        <cylinder length="0.05" radius="0.015"/>
      </geometry>
    </collision>
    <collision name="gps_collision_antenna">
      <origin rpy="0 0 0" xyz="0 0 0.11"/>
      <geometry>
        <cylinder length="0.1" radius="0.15"/>
      </geometry>
    </collision>
    <inertial>
      <mass value="1"/>
      <inertia ixx="0.006458" ixy="0.0" ixz="0.0" iyy="0.006458" iyz="0.0" izz="0.01125"/>
    </inertial>
  </link>
  <joint name="aquabot/gps_joint" type="revolute">
    <axis xyz="0 0 1"/>
    <limit effort="1000.0" lower="0.0" upper="0" velocity="0"/>
    <origin rpy="0.0 0.0 0.0" xyz="0.0 0.0 1.3"/>
    <parent link="aquabot/base_link"/>
    <child link="aquabot/gps_link"/>
  </joint>
  <gazebo reference="aquabot/gps_link">
    <sensor name="navsat" type="navsat">
      <always_on>1</always_on>
      <update_rate>20</update_rate>
      <!--<topic>${namespace}/${sensor_namespace}gps/gps/fix</topic>-->
    </sensor>
  </gazebo>
  <link name="aquabot/imu_link">
    <visual name="imu_visual">
      <geometry>
        <box size="0.05 0.025 0.005"/>
      </geometry>
      <material name="imu_visual_material">
        <color rgba="1.0 0.0 00 1.0"/>
      </material>
    </visual>
    <collision name="imu_collision">
      <geometry>
        <box size="0.05 0.025 0.005"/>
      </geometry>
    </collision>
    <inertial>
      <mass value="0.1"/>
      <inertia ixx="0.00000542" ixy="0.0" ixz="0.0" iyy="0.00002104" iyz="0.0" izz="0.00002604"/>
    </inertial>
  </link>
  <joint name="aquabot/imu_joint" type="revolute">
    <axis xyz="0 0 1"/>
    <limit effort="1000.0" lower="0.0" upper="0" velocity="0"/>
    <origin rpy="0.0 0.0 0.0" xyz="1.0 0.0 1.62"/>
    <parent link="aquabot/base_link"/>
    <child link="aquabot/imu_link"/>
  </joint>
  <gazebo reference="aquabot/imu_link">
    <sensor name="imu_sensor" type="imu">
      <update_rate>100</update_rate>
      <imu>
        <angular_velocity>
          <x>
            <noise type="gaussian">
              <mean>0</mean>
              <stddev>0.009</stddev>
              <bias_mean>0.00075</bias_mean>
              <bias_stddev>0.005</bias_stddev>
              <dynamic_bias_stddev>0.00002</dynamic_bias_stddev>
              <dynamic_bias_correlation_time>400.0</dynamic_bias_correlation_time>
              <precision>0.00025</precision>
            </noise>
          </x>
          <y>
            <noise type="gaussian">
              <mean>0</mean>
              <stddev>0.009</stddev>
              <bias_mean>0.00075</bias_mean>
              <bias_stddev>0.005</bias_stddev>
              <dynamic_bias_stddev>0.00002</dynamic_bias_stddev>
              <dynamic_bias_correlation_time>400.0</dynamic_bias_correlation_time>
              <precision>0.00025</precision>
            </noise>
          </y>
          <z>
            <noise type="gaussian">
              <mean>0</mean>
              <stddev>0.009</stddev>
              <bias_mean>0.00075</bias_mean>
              <bias_stddev>0.005</bias_stddev>
              <dynamic_bias_stddev>0.00002</dynamic_bias_stddev>
              <dynamic_bias_correlation_time>400.0</dynamic_bias_correlation_time>
              <precision>0.00025</precision>
            </noise>
          </z>
        </angular_velocity>
        <linear_acceleration>
          <x>
            <noise type="gaussian">
              <mean>0</mean>
              <stddev>0.021</stddev>
              <bias_mean>0.05</bias_mean>
              <bias_stddev>0.0075</bias_stddev>
              <dynamic_bias_stddev>0.000375</dynamic_bias_stddev>
              <dynamic_bias_correlation_time>175.0</dynamic_bias_correlation_time>
              <precision>0.005</precision>
            </noise>
          </x>
          <y>
            <noise type="gaussian">
              <mean>0</mean>
              <stddev>0.021</stddev>
              <bias_mean>0.05</bias_mean>
              <bias_stddev>0.0075</bias_stddev>
              <dynamic_bias_stddev>0.000375</dynamic_bias_stddev>
              <dynamic_bias_correlation_time>175.0</dynamic_bias_correlation_time>
              <precision>0.005</precision>
            </noise>
          </y>
          <z>
            <noise type="gaussian">
              <mean>0</mean>
              <stddev>0.021</stddev>
              <bias_mean>0.05</bias_mean>
              <bias_stddev>0.0075</bias_stddev>
              <dynamic_bias_stddev>0.000375</dynamic_bias_stddev>
              <dynamic_bias_correlation_time>175.0</dynamic_bias_correlation_time>
              <precision>0.005</precision>
            </noise>
          </z>
        </linear_acceleration>
        <orientation_reference_frame>
          <localization>ENU</localization>
        </orientation_reference_frame>
      </imu>
    </sensor>
  </gazebo>
  <link name="aquabot/receiver">
    <visual>
      <origin rpy="0 0 0" xyz="0 0 0"/>
      <geometry>
        <sphere radius="0.01"/>
      </geometry>
    </visual>
    <inertial>
      <mass value="0.1"/>
      <inertia ixx="0.00000542" ixy="0.0" ixz="0.0" iyy="0.00002104" iyz="0.0" izz="0.00002604"/>
    </inertial>
  </link>
  <joint name="aquabot/receiver_pinger_joint" type="revolute">
    <axis xyz="0 0 1"/>
    <limit effort="1000.0" lower="0.0" upper="0" velocity="0"/>
    <origin rpy="0 0 0" xyz="0 0 0"/>
    <parent link="aquabot/base_link"/>
    <child link="aquabot/receiver"/>
  </joint>
  <gazebo>
    <plugin filename="libAcousticPingerPlugin.so" name="vrx::AcousticPingerPlugin">
      <position>1.0 0 -1.0</position>
      <topic>/aquabot/sensors/acoustics/receiver</topic>
      <set_position_topic>/pinger/set_pinger_position
        </set_position_topic>
      <frame_id>pinger</frame_id>
      <range_noise>
        <noise>
          <type>gaussian</type>
          <mean>0.0</mean>
          <stddev>3.0</stddev>
        </noise>
      </range_noise>
      <bearing_noise>
        <noise>
          <type>gaussian</type>
          <mean>0.0</mean>
          <stddev>0.01</stddev>
        </noise>
      </bearing_noise>
      <elevation_noise>
        <noise>
          <type>gaussian</type>
          <mean>0.0</mean>
          <stddev>0.01</stddev>
        </noise>
      </elevation_noise>
    </plugin>
  </gazebo>
</robot>


